Workbook

Sheet Collections
A1: KingdomCity Church Nanyuki
A2: Collections Budget 2026
A4: Date | B4: Sunday | C4: Cash (KES) | D4: Paybill (KES) | E4: Weekly Total (KES) | F4: Running Balance (KES) | G4: Notes
A5: JANUARY 2026
A6: 46026 | B6: Sunday 1 | C6: 0 | D6: 0 | E6: =C6+D6 -> 0 | F6: =SUM(E6) -> 0
A7: 46033 | B7: Sunday 2 | C7: 0 | D7: 0 | E7: =C7+D7 -> 0 | F7: =SUM(E6,E7) -> 0
A8: 46040 | B8: Sunday 3 | C8: 0 | D8: 0 | E8: =C8+D8 -> 0 | F8: =SUM(E6,E7,E8) -> 0
A9: 46047 | B9: Sunday 4 | C9: 0 | D9: 0 | E9: =C9+D9 -> 0 | F9: =SUM(E6,E7,E8,E9) -> 0
A10: Total – JANUARY | C10: =SUM(C6:C9) -> 0 | D10: =SUM(D6:D9) -> 0 | E10: =SUM(E6:E9) -> 0 | F10: =SUM(E6,E7,E8,E9) -> 0
A11: FEBRUARY 2026
A12: 46054 | B12: Sunday 1 | C12: 0 | D12: 0 | E12: =C12+D12 -> 0 | F12: =SUM(E6,E7,E8,E9,E12) -> 0
A13: 46061 | B13: Sunday 2 | C13: 0 | D13: 0 | E13: =C13+D13 -> 0 | F13: =SUM(E6,E7,E8,E9,E12,E13) -> 0
A14: 46068 | B14: Sunday 3 | C14: 0 | D14: 0 | E14: =C14+D14 -> 0 | F14: =SUM(E6,E7,E8,E9,E12,E13,E14) -> 0
A15: 46075 | B15: Sunday 4 | C15: 0 | D15: 0 | E15: =C15+D15 -> 0 | F15: =SUM(E6,E7,E8,E9,E12,E13,E14,E15) -> 0
A16: Total – FEBRUARY | C16: =SUM(C12:C15) -> 0 | D16: =SUM(D12:D15) -> 0 | E16: =SUM(E12:E15) -> 0 | F16: =SUM(E6,E7,E8,E9,E12,E13,E14,E15) -> 0
A17: MARCH 2026
A18: 46082 | B18: Sunday 1 | D18: 0 | E18: =C18+D18 -> 0 | F18: =SUM(E6,E7,E8,E9,E12,E13,E14,E15,E18) -> 0 | G18: Paybill collections haven't been populated
A19: 46089 | B19: Sunday 2 | C19: 3160 | D19: 0 | E19: =C19+D19 -> 3160 | F19: =SUM(E6,E7,E8,E9,E12,E13,E14,E15,E18,E19) -> 3160 | G19: Cheque no. 2 was unpaid due to the Bank's failure update instructions for the same
A20: 46096 | B20: Sunday 3 | C20: 6310 | D20: 0 | E20: =C20+D20 -> 6310 | F20: =SUM(E6,E7,E8,E9,E12,E13,E14,E15,E18,E19,E20) -> 9470
A21: 46103 | B21: Sunday 4 | C21: 4680 | D21: 0 | E21: =C21+D21 -> 4680 | F21: =SUM(E6,E7,E8,E9,E12,E13,E14,E15,E18,E19,E20,E21) -> 14150
A22: 46110 | B22: Sunday 5 | C22: 4620 | D22: 0 | E22: =C22+D22 -> 4620 | F22: =SUM(E6,E7,E8,E9,E12,E13,E14,E15,E18,E19,E20,E21,E22) -> 18770
A23: Total – MARCH | C23: =SUM(C18:C22) -> 18770 | D23: =SUM(D18:D22) -> 0 | E23: =SUM(E18:E22) -> 18770 | F23: =SUM(E6,E7,E8,E9,E12,E13,E14,E15,E18,E19,E20,E21,E22) -> 18770
A24: APRIL 2026
A25: 46117 | B25: Sunday 1 | C25: 12780 | D25: 0 | E25: =C25+D25 -> 12780 | F25: =SUM(E6,E7,E8,E9,E12,E13,E14,E15,E18,E19,E20,E21,E22,E25) -> 31550
A26: 46124 | B26: Sunday 2 | C26: 6280 | D26: 0 | E26: =C26+D26 -> 6280 | F26: =SUM(E6,E7,E8,E9,E12,E13,E14,E15,E18,E19,E20,E21,E22,E25,E26) -> 37830
A27: 46131 | B27: Sunday 3 | C27: 7530.5 | D27: 0 | E27: =C27+D27 -> 7530.5 | F27: =SUM(E6,E7,E8,E9,E12,E13,E14,E15,E18,E19,E20,E21,E22,E25,E26,E27) -> 45360.5
A28: 46138 | B28: Sunday 4 | C28: 6600 | D28: 0 | E28: =C28+D28 -> 6600 | F28: =SUM(E6,E7,E8,E9,E12,E13,E14,E15,E18,E19,E20,E21,E22,E25,E26,E27,E28) -> 51960.5
A29: Total – APRIL | C29: =SUM(C25:C28) -> 33190.5 | D29: =SUM(D25:D28) -> 0 | E29: =SUM(E25:E28) -> 33190.5 | F29: =SUM(E6,E7,E8,E9,E12,E13,E14,E15,E18,E19,E20,E21,E22,E25,E26,E27,E28) -> 51960.5
A30: MAY 2026
A31: 46145 | B31: Sunday 1 | C31: 2740 | D31: 0 | E31: =C31+D31 -> 2740 | F31: =SUM(E6,E7,E8,E9,E12,E13,E14,E15,E18,E19,E20,E21,E22,E25,E26,E27,E28,E31) -> 54700.5
A32: 46152 | B32: Sunday 2 | C32: 2770 | D32: 0 | E32: =C32+D32 -> 2770 | F32: =SUM(E6,E7,E8,E9,E12,E13,E14,E15,E18,E19,E20,E21,E22,E25,E26,E27,E28,E31,E32) -> 57470.5
A33: 46159 | B33: Sunday 3 | C33: 11371 | D33: 0 | E33: =C33+D33 -> 11371 | F33: =SUM(E6,E7,E8,E9,E12,E13,E14,E15,E18,E19,E20,E21,E22,E25,E26,E27,E28,E31,E32,E33) -> 68841.5
A34: 46166 | B34: Sunday 4 | C34: 4110 | D34: 0 | E34: =C34+D34 -> 4110 | F34: =SUM(E6,E7,E8,E9,E12,E13,E14,E15,E18,E19,E20,E21,E22,E25,E26,E27,E28,E31,E32,E33,E34) -> 72951.5
A35: 46173 | B35: Sunday 5 | C35: 1790 | D35: 0 | E35: =C35+D35 -> 1790 | F35: =SUM(E6,E7,E8,E9,E12,E13,E14,E15,E18,E19,E20,E21,E22,E25,E26,E27,E28,E31,E32,E33,E34,E35) -> 74741.5
A36: Total – MAY | C36: =SUM(C31:C35) -> 22781 | D36: =SUM(D31:D35) -> 0 | E36: =SUM(E31:E35) -> 22781 | F36: =SUM(E6,E7,E8,E9,E12,E13,E14,E15,E18,E19,E20,E21,E22,E25,E26,E27,E28,E31,E32,E33,E34,E35) -> 74741.5
A37: JUNE 2026
A38: 46180 | B38: Sunday 1 | C38: 3545 | D38: 0 | E38: =C38+D38 -> 3545 | F38: =SUM(E6,E7,E8,E9,E12,E13,E14,E15,E18,E19,E20,E21,E22,E25,E26,E27,E28,E31,E32,E33,E34,E35,E38) -> 78286.5
A39: 46187 | B39: Sunday 2 | C39: 0 | D39: 0 | E39: =C39+D39 -> 0 | F39: =SUM(E6,E7,E8,E9,E12,E13,E14,E15,E18,E19,E20,E21,E22,E25,E26,E27,E28,E31,E32,E33,E34,E35,E38,E39) -> 78286.5
A40: 46194 | B40: Sunday 3 | C40: 0 | D40: 0 | E40: =C40+D40 -> 0 | F40: =SUM(E6,E7,E8,E9,E12,E13,E14,E15,E18,E19,E20,E21,E22,E25,E26,E27,E28,E31,E32,E33,E34,E35,E38,E39,E40) -> 78286.5
A41: 46201 | B41: Sunday 4 | C41: 0 | D41: 0 | E41: =C41+D41 -> 0 | F41: =SUM(E6,E7,E8,E9,E12,E13,E14,E15,E18,E19,E20,E21,E22,E25,E26,E27,E28,E31,E32,E33,E34,E35,E38,E39,E40,E41) -> 78286.5
...

Sheet Expenses
A1: Kingdom City Church Nanyuki
A2: Weekly Expenses Budget 2026
A4: MONTH | C4: JANUARY | H4: FEBRUARY | M4: MARCH | S4: APRIL | X4: MAY | AD4: JUNE | AI4: JULY | AN4: AUGUST | AT4: SEPTEMBER | AY4: OCTOBER | BD4: NOVEMBER | BJ4: DECEMBER | BO4: YEAR TOTAL
A5: DATE | C5: 46026 | D5: 46033 | E5: 46040 | F5: 46047 | G5: JANUARY | H5: 46054 | I5: 46061 | J5: 46068 | K5: 46075 | L5: FEBRUARY | M5: 46082 | N5: 46089 | O5: 46096 | P5: 46103 | Q5: 46110 | R5: MARCH | S5: 46117 | T5: 46124 | U5: 46131 | V5: 46138 | W5: APRIL | X5: 46145 | Y5: 46152 | Z5: 46159 | AA5: 46166 | AB5: 46173 | AC5: MAY | AD5: 46180 | AE5: 46187 | AF5: 46194 | AG5: 46201 | AH5: JUNE | AI5: 46208 | AJ5: 46215 | AK5: 46222 | AL5: 46229 | AM5: JULY | AN5: 46236 | AO5: 46243 | AP5: 46250 | AQ5: 46257 | AR5: 46264 | AS5: AUGUST | AT5: 46271 | AU5: 46278 | AV5: 46285 | AW5: 46292 | AX5: SEPTEMBER | AY5: 46299 | AZ5: 46306 | BA5: 46313 | BB5: 46320 | BC5: OCTOBER | BD5: 46327 | BE5: 46334 | BF5: 46341 | BG5: 46348 | BH5: 46355 | BI5: NOVEMBER | BJ5: 46362 | BK5: 46369 | BL5: 46376 | BM5: 46383 | BN5: DECEMBER | BO5: YEAR
A6: SUNDAY | C6: Sun 1 | D6: Sun 2 | E6: Sun 3 | F6: Sun 4 | G6: TOTAL | H6: Sun 1 | I6: Sun 2 | J6: Sun 3 | K6: Sun 4 | L6: TOTAL | M6: Sun 1 | N6: Sun 2 | O6: Sun 3 | P6: Sun 4 | Q6: Sun 5 | R6: TOTAL | S6: Sun 1 | T6: Sun 2 | U6: Sun 3 | V6: Sun 4 | W6: TOTAL | X6: Sun 1 | Y6: Sun 2 | Z6: Sun 3 | AA6: Sun 4 | AB6: Sun 5 | AC6: TOTAL | AD6: Sun 1 | AE6: Sun 2 | AF6: Sun 3 | AG6: Sun 4 | AH6: TOTAL | AI6: Sun 1 | AJ6: Sun 2 | AK6: Sun 3 | AL6: Sun 4 | AM6: TOTAL | AN6: Sun 1 | AO6: Sun 2 | AP6: Sun 3 | AQ6: Sun 4 | AR6: Sun 5 | AS6: TOTAL | AT6: Sun 1 | AU6: Sun 2 | AV6: Sun 3 | AW6: Sun 4 | AX6: TOTAL | AY6: Sun 1 | AZ6: Sun 2 | BA6: Sun 3 | BB6: Sun 4 | BC6: TOTAL | BD6: Sun 1 | BE6: Sun 2 | BF6: Sun 3 | BG6: Sun 4 | BH6: Sun 5 | BI6: TOTAL | BJ6: Sun 1 | BK6: Sun 2 | BL6: Sun 3 | BM6: Sun 4 | BN6: TOTAL | BO6: TOTAL
A7: Keyboardist | B7: Sunday allowance | C7: 0 | D7: 0 | E7: 0 | F7: 0 | G7: =SUM(C7:F7) -> 0 | H7: 0 | I7: 0 | J7: 0 | K7: 0 | L7: =SUM(H7:K7) -> 0 | N7: 2500 | O7: 2500 | P7: 2500 | Q7: 2500 | R7: =SUM(M7:Q7) -> 10000 | S7: 2500 | T7: 2500 | U7: 2500 | V7: 2500 | W7: =SUM(S7:V7) -> 10000 | X7: 2500 | Y7: 2500 | Z7: 2500 | AA7: 2500 | AB7: 2500 | AC7: =SUM(X7:AB7) -> 12500 | AD7: 2500 | AE7: 0 | AF7: 0 | AG7: 0 | AH7: =SUM(AD7:AG7) -> 2500 | AI7: 0 | AJ7: 0 | AK7: 0 | AL7: 0 | AM7: =SUM(AI7:AL7) -> 0 | AN7: 0 | AO7: 0 | AP7: 0 | AQ7: 0 | AR7: 0 | AS7: =SUM(AN7:AR7) -> 0 | AT7: 0 | AU7: 0 | AV7: 0 | AW7: 0 | AX7: =SUM(AT7:AW7) -> 0 | AY7: 0 | AZ7: 0 | BA7: 0 | BB7: 0 | BC7: =SUM(AY7:BB7) -> 0 | BD7: 0 | BE7: 0 | BF7: 0 | BG7: 0 | BH7: 0 | BI7: =SUM(BD7:BH7) -> 0 | BJ7: 0 | BK7: 0 | BL7: 0 | BM7: 0 | BN7: =SUM(BJ7:BM7) -> 0 | BO7: =SUM(C7,D7,E7,F7,H7,I7,J7,K7,M7,N7,O7,P7,Q7,S7,T7,U7,V7,X7,Y7,Z7,AA7,AB7,AD7,AE7,AF7,AG7,AI7,AJ7,AK7,AL7,AN7,AO7,AP7,AQ7,AR7,AT7,AU7,AV7,AW7,AY7,AZ7,BA7,BB7,BD7,BE7,BF7,BG7,BH7,BJ7,BK7,BL7,BM7) -> 35000
A8: Drummer | B8: Sunday allowance | C8: 0 | D8: 0 | E8: 0 | F8: 0 | G8: =SUM(C8:F8) -> 0 | H8: 0 | I8: 0 | J8: 0 | K8: 0 | L8: =SUM(H8:K8) -> 0 | N8: 2500 | O8: 2500 | P8: 2500 | Q8: 2500 | R8: =SUM(M8:Q8) -> 10000 | S8: 2500 | T8: 2500 | U8: 2500 | V8: 2500 | W8: =SUM(S8:V8) -> 10000 | X8: 2500 | Y8: 2500 | Z8: 2500 | AA8: 2500 | AB8: 2500 | AC8: =SUM(X8:AB8) -> 12500 | AD8: 2500 | AE8: 0 | AF8: 0 | AG8: 0 | AH8: =SUM(AD8:AG8) -> 2500 | AI8: 0 | AJ8: 0 | AK8: 0 | AL8: 0 | AM8: =SUM(AI8:AL8) -> 0 | AN8: 0 | AO8: 0 | AP8: 0 | AQ8: 0 | AR8: 0 | AS8: =SUM(AN8:AR8) -> 0 | AT8: 0 | AU8: 0 | AV8: 0 | AW8: 0 | AX8: =SUM(AT8:AW8) -> 0 | AY8: 0 | AZ8: 0 | BA8: 0 | BB8: 0 | BC8: =SUM(AY8:BB8) -> 0 | BD8: 0 | BE8: 0 | BF8: 0 | BG8: 0 | BH8: 0 | BI8: =SUM(BD8:BH8) -> 0 | BJ8: 0 | BK8: 0 | BL8: 0 | BM8: 0 | BN8: =SUM(BJ8:BM8) -> 0 | BO8: =SUM(C8,D8,E8,F8,H8,I8,J8,K8,M8,N8,O8,P8,Q8,S8,T8,U8,V8,X8,Y8,Z8,AA8,AB8,AD8,AE8,AF8,AG8,AI8,AJ8,AK8,AL8,AN8,AO8,AP8,AQ8,AR8,AT8,AU8,AV8,AW8,AY8,AZ8,BA8,BB8,BD8,BE8,BF8,BG8,BH8,BJ8,BK8,BL8,BM8) -> 35000
A9: Kids Teacher | B9: Sunday allowance | C9: 0 | D9: 0 | E9: 0 | F9: 0 | G9: =SUM(C9:F9) -> 0 | H9: 0 | I9: 0 | J9: 0 | K9: 0 | L9: =SUM(H9:K9) -> 0 | N9: 2500 | O9: 2500 | P9: 2500 | Q9: 2500 | R9: =SUM(M9:Q9) -> 10000 | S9: 2500 | T9: 0 | U9: 0 | V9: 0 | W9: =SUM(S9:V9) -> 2500 | X9: 0 | Y9: 0 | Z9: 0 | AA9: 0 | AB9: 0 | AC9: =SUM(X9:AB9) -> 0 | AD9: 0 | AE9: 0 | AF9: 0 | AG9: 0 | AH9: =SUM(AD9:AG9) -> 0 | AI9: 0 | AJ9: 0 | AK9: 0 | AL9: 0 | AM9: =SUM(AI9:AL9) -> 0 | AN9: 0 | AO9: 0 | AP9: 0 | AQ9: 0 | AR9: 0 | AS9: =SUM(AN9:AR9) -> 0 | AT9: 0 | AU9: 0 | AV9: 0 | AW9: 0 | AX9: =SUM(AT9:AW9) -> 0 | AY9: 0 | AZ9: 0 | BA9: 0 | BB9: 0 | BC9: =SUM(AY9:BB9) -> 0 | BD9: 0 | BE9: 0 | BF9: 0 | BG9: 0 | BH9: 0 | BI9: =SUM(BD9:BH9) -> 0 | BJ9: 0 | BK9: 0 | BL9: 0 | BM9: 0 | BN9: =SUM(BJ9:BM9) -> 0 | BO9: =SUM(C9,D9,E9,F9,H9,I9,J9,K9,M9,N9,O9,P9,Q9,S9,T9,U9,V9,X9,Y9,Z9,AA9,AB9,AD9,AE9,AF9,AG9,AI9,AJ9,AK9,AL9,AN9,AO9,AP9,AQ9,AR9,AT9,AU9,AV9,AW9,AY9,AZ9,BA9,BB9,BD9,BE9,BF9,BG9,BH9,BJ9,BK9,BL9,BM9) -> 12500
A10: Caretaker | B10: Sunday allowance | C10: 0 | D10: 0 | E10: 0 | F10: 0 | G10: =SUM(C10:F10) -> 0 | H10: 0 | I10: 0 | J10: 0 | K10: 0 | L10: =SUM(H10:K10) -> 0 | N10: 4200 | O10: 4200 | P10: 4200 | Q10: 4200 | R10: =SUM(M10:Q10) -> 16800 | S10: 4200 | T10: 4200 | U10: 4200 | V10: 4200 | W10: =SUM(S10:V10) -> 16800 | X10: 4200 | Y10: 4200 | Z10: 4200 | AA10: 4200 | AB10: 4200 | AC10: =SUM(X10:AB10) -> 21000 | AD10: 4200 | AE10: 0 | AF10: 0 | AG10: 0 | AH10: =SUM(AD10:AG10) -> 4200 | AI10: 0 | AJ10: 0 | AK10: 0 | AL10: 0 | AM10: =SUM(AI10:AL10) -> 0 | AN10: 0 | AO10: 0 | AP10: 0 | AQ10: 0 | AR10: 0 | AS10: =SUM(AN10:AR10) -> 0 | AT10: 0 | AU10: 0 | AV10: 0 | AW10: 0 | AX10: =SUM(AT10:AW10) -> 0 | AY10: 0 | AZ10: 0 | BA10: 0 | BB10: 0 | BC10: =SUM(AY10:BB10) -> 0 | BD10: 0 | BE10: 0 | BF10: 0 | BG10: 0 | BH10: 0 | BI10: =SUM(BD10:BH10) -> 0 | BJ10: 0 | BK10: 0 | BL10: 0 | BM10: 0 | BN10: =SUM(BJ10:BM10) -> 0 | BO10: =SUM(C10,D10,E10,F10,H10,I10,J10,K10,M10,N10,O10,P10,Q10,S10,T10,U10,V10,X10,Y10,Z10,AA10,AB10,AD10,AE10,AF10,AG10,AI10,AJ10,AK10,AL10,AN10,AO10,AP10,AQ10,AR10,AT10,AU10,AV10,AW10,AY10,AZ10,BA10,BB10,BD10,BE10,BF10,BG10,BH10,BJ10,BK10,BL10,BM10) -> 58800
A11: Honorarium & Gifts | C11: 0 | D11: 0 | E11: 0 | F11: 0 | G11: =SUM(C11:F11) -> 0 | H11: 0 | I11: 0 | J11: 0 | K11: 0 | L11: =SUM(H11:K11) -> 0 | N11: 2500 | O11: 5000 | P11: 5000 | Q11: 5000 | R11: =SUM(M11:Q11) -> 17500 | S11: 5000 | T11: 0 | U11: 0 | V11: 0 | W11: =SUM(S11:V11) -> 5000 | X11: 0 | Y11: 0 | Z11: 0 | AA11: 0 | AB11: 0 | AC11: =SUM(X11:AB11) -> 0 | AD11: 0 | AE11: 0 | AF11: 0 | AG11: 0 | AH11: =SUM(AD11:AG11) -> 0 | AI11: 0 | AJ11: 0 | AK11: 0 | AL11: 0 | AM11: =SUM(AI11:AL11) -> 0 | AN11: 0 | AO11: 0 | AP11: 0 | AQ11: 0 | AR11: 0 | AS11: =SUM(AN11:AR11) -> 0 | AT11: 0 | AU11: 0 | AV11: 0 | AW11: 0 | AX11: =SUM(AT11:AW11) -> 0 | AY11: 0 | AZ11: 0 | BA11: 0 | BB11: 0 | BC11: =SUM(AY11:BB11) -> 0 | BD11: 0 | BE11: 0 | BF11: 0 | BG11: 0 | BH11: 0 | BI11: =SUM(BD11:BH11) -> 0 | BJ11: 0 | BK11: 0 | BL11: 0 | BM11: 0 | BN11: =SUM(BJ11:BM11) -> 0 | BO11: =SUM(C11,D11,E11,F11,H11,I11,J11,K11,M11,N11,O11,P11,Q11,S11,T11,U11,V11,X11,Y11,Z11,AA11,AB11,AD11,AE11,AF11,AG11,AI11,AJ11,AK11,AL11,AN11,AO11,AP11,AQ11,AR11,AT11,AU11,AV11,AW11,AY11,AZ11,BA11,BB11,BD11,BE11,BF11,BG11,BH11,BJ11,BK11,BL11,BM11) -> 22500
A12: KPLC Tokens | B12: Weekly usage | C12: 0 | D12: 0 | E12: 0 | F12: 0 | G12: =SUM(C12:F12) -> 0 | H12: 0 | I12: 0 | J12: 0 | K12: 0 | L12: =SUM(H12:K12) -> 0 | N12: 500 | O12: 500 | P12: 500 | Q12: 500 | R12: =SUM(M12:Q12) -> 2000 | S12: 500 | T12: 500 | U12: 500 | V12: 500 | W12: =SUM(S12:V12) -> 2000 | X12: 500 | Y12: 500 | Z12: 500 | AA12: 500 | AB12: 500 | AC12: =SUM(X12:AB12) -> 2500 | AD12: 500 | AE12: 0 | AF12: 0 | AG12: 0 | AH12: =SUM(AD12:AG12) -> 500 | AI12: 0 | AJ12: 0 | AK12: 0 | AL12: 0 | AM12: =SUM(AI12:AL12) -> 0 | AN12: 0 | AO12: 0 | AP12: 0 | AQ12: 0 | AR12: 0 | AS12: =SUM(AN12:AR12) -> 0 | AT12: 0 | AU12: 0 | AV12: 0 | AW12: 0 | AX12: =SUM(AT12:AW12) -> 0 | AY12: 0 | AZ12: 0 | BA12: 0 | BB12: 0 | BC12: =SUM(AY12:BB12) -> 0 | BD12: 0 | BE12: 0 | BF12: 0 | BG12: 0 | BH12: 0 | BI12: =SUM(BD12:BH12) -> 0 | BJ12: 0 | BK12: 0 | BL12: 0 | BM12: 0 | BN12: =SUM(BJ12:BM12) -> 0 | BO12: =SUM(C12,D12,E12,F12,H12,I12,J12,K12,M12,N12,O12,P12,Q12,S12,T12,U12,V12,X12,Y12,Z12,AA12,AB12,AD12,AE12,AF12,AG12,AI12,AJ12,AK12,AL12,AN12,AO12,AP12,AQ12,AR12,AT12,AU12,AV12,AW12,AY12,AZ12,BA12,BB12,BD12,BE12,BF12,BG12,BH12,BJ12,BK12,BL12,BM12) -> 7000
A13: Bassist | C13: 0 | D13: 0 | E13: 0 | F13: 0 | G13: =SUM(C13:F13) -> 0 | H13: 0 | I13: 0 | J13: 0 | K13: 0 | L13: =SUM(H13:K13) -> 0 | N13: 0 | O13: 0 | P13: 0 | Q13: 0 | R13: =SUM(M13:Q13) -> 0 | S13: 0 | T13: 0 | U13: 0 | V13: 0 | W13: =SUM(S13:V13) -> 0 | X13: 0 | Y13: 0 | Z13: 0 | AA13: 0 | AB13: 2500 | AC13: =SUM(X13:AB13) -> 2500 | AD13: 0 | AE13: 0 | AF13: 0 | AG13: 0 | AH13: =SUM(AD13:AG13) -> 0 | AI13: 0 | AJ13: 0 | AK13: 0 | AL13: 0 | AM13: =SUM(AI13:AL13) -> 0 | AN13: 0 | AO13: 0 | AP13: 0 | AQ13: 0 | AR13: 0 | AS13: =SUM(AN13:AR13) -> 0 | AT13: 0 | AU13: 0 | AV13: 0 | AW13: 0 | AX13: =SUM(AT13:AW13) -> 0 | AY13: 0 | AZ13: 0 | BA13: 0 | BB13: 0 | BC13: =SUM(AY13:BB13) -> 0 | BD13: 0 | BE13: 0 | BF13: 0 | BG13: 0 | BH13: 0 | BI13: =SUM(BD13:BH13) -> 0 | BJ13: 0 | BK13: 0 | BL13: 0 | BM13: 0 | BN13: =SUM(BJ13:BM13) -> 0 | BO13: =SUM(C13,D13,E13,F13,H13,I13,J13,K13,M13,N13,O13,P13,Q13,S13,T13,U13,V13,X13,Y13,Z13,AA13,AB13,AD13,AE13,AF13,AG13,AI13,AJ13,AK13,AL13,AN13,AO13,AP13,AQ13,AR13,AT13,AU13,AV13,AW13,AY13,AZ13,BA13,BB13,BD13,BE13,BF13,BG13,BH13,BJ13,BK13,BL13,BM13) -> 2500
A14: WEEKLY TOTAL | C14: =SUM(C7,C8,C9,C10,C11,C12,C13) -> 0 | D14: =SUM(D7,D8,D9,D10,D11,D12,D13) -> 0 | E14: =SUM(E7,E8,E9,E10,E11,E12,E13) -> 0 | F14: =SUM(F7,F8,F9,F10,F11,F12,F13) -> 0 | G14: =SUM(G7:G13) -> 0 | H14: =SUM(H7,H8,H9,H10,H11,H12,H13) -> 0 | I14: =SUM(I7,I8,I9,I10,I11,I12,I13) -> 0 | J14: =SUM(J7,J8,J9,J10,J11,J12,J13) -> 0 | K14: =SUM(K7,K8,K9,K10,K11,K12,K13) -> 0 | L14: =SUM(L7:L13) -> 0 | M14: =SUM(M7,M8,M9,M10,M11,M12,M13) -> 0 | N14: =SUM(N7,N8,N9,N10,N11,N12,N13) -> 14700 | O14: =SUM(O7,O8,O9,O10,O11,O12,O13) -> 17200 | P14: =SUM(P7,P8,P9,P10,P11,P12,P13) -> 17200 | Q14: =SUM(Q7,Q8,Q9,Q10,Q11,Q12,Q13) -> 17200 | R14: =SUM(R7:R13) -> 66300 | S14: =SUM(S7,S8,S9,S10,S11,S12,S13) -> 17200 | T14: =SUM(T7,T8,T9,T10,T11,T12,T13) -> 9700 | U14: =SUM(U7,U8,U9,U10,U11,U12,U13) -> 9700 | V14: =SUM(V7,V8,V9,V10,V11,V12,V13) -> 9700 | W14: =SUM(W7:W13) -> 46300 | X14: =SUM(X7,X8,X9,X10,X11,X12,X13) -> 9700 | Y14: =SUM(Y7,Y8,Y9,Y10,Y11,Y12,Y13) -> 9700 | Z14: =SUM(Z7,Z8,Z9,Z10,Z11,Z12,Z13) -> 9700 | AA14: =SUM(AA7,AA8,AA9,AA10,AA11,AA12,AA13) -> 9700 | AB14: =SUM(AB7,AB8,AB9,AB10,AB11,AB12,AB13) -> 12200 | AC14: =SUM(AC7:AC13) -> 51000 | AD14: =SUM(AD7,AD8,AD9,AD10,AD11,AD12,AD13) -> 9700 | AE14: =SUM(AE7,AE8,AE9,AE10,AE11,AE12,AE13) -> 0 | AF14: =SUM(AF7,AF8,AF9,AF10,AF11,AF12,AF13) -> 0 | AG14: =SUM(AG7,AG8,AG9,AG10,AG11,AG12,AG13) -> 0 | AH14: =SUM(AH7:AH13) -> 9700 | AI14: =SUM(AI7,AI8,AI9,AI10,AI11,AI12,AI13) -> 0 | AJ14: =SUM(AJ7,AJ8,AJ9,AJ10,AJ11,AJ12,AJ13) -> 0 | AK14: =SUM(AK7,AK8,AK9,AK10,AK11,AK12,AK13) -> 0 | AL14: =SUM(AL7,AL8,AL9,AL10,AL11,AL12,AL13) -> 0 | AM14: =SUM(AM7:AM13) -> 0 | AN14: =SUM(AN7,AN8,AN9,AN10,AN11,AN12,AN13) -> 0 | AO14: =SUM(AO7,AO8,AO9,AO10,AO11,AO12,AO13) -> 0 | AP14: =SUM(AP7,AP8,AP9,AP10,AP11,AP12,AP13) -> 0 | AQ14: =SUM(AQ7,AQ8,AQ9,AQ10,AQ11,AQ12,AQ13) -> 0 | AR14: =SUM(AR7,AR8,AR9,AR10,AR11,AR12,AR13) -> 0 | AS14: =SUM(AS7:AS13) -> 0 | AT14: =SUM(AT7,AT8,AT9,AT10,AT11,AT12,AT13) -> 0 | AU14: =SUM(AU7,AU8,AU9,AU10,AU11,AU12,AU13) -> 0 | AV14: =SUM(AV7,AV8,AV9,AV10,AV11,AV12,AV13) -> 0 | AW14: =SUM(AW7,AW8,AW9,AW10,AW11,AW12,AW13) -> 0 | AX14: =SUM(AX7:AX13) -> 0 | AY14: =SUM(AY7,AY8,AY9,AY10,AY11,AY12,AY13) -> 0 | AZ14: =SUM(AZ7,AZ8,AZ9,AZ10,AZ11,AZ12,AZ13) -> 0 | BA14: =SUM(BA7,BA8,BA9,BA10,BA11,BA12,BA13) -> 0 | BB14: =SUM(BB7,BB8,BB9,BB10,BB11,BB12,BB13) -> 0 | BC14: =SUM(BC7:BC13) -> 0 | BD14: =SUM(BD7,BD8,BD9,BD10,BD11,BD12,BD13) -> 0 | BE14: =SUM(BE7,BE8,BE9,BE10,BE11,BE12,BE13) -> 0 | BF14: =SUM(BF7,BF8,BF9,BF10,BF11,BF12,BF13) -> 0 | BG14: =SUM(BG7,BG8,BG9,BG10,BG11,BG12,BG13) -> 0 | BH14: =SUM(BH7,BH8,BH9,BH10,BH11,BH12,BH13) -> 0 | BI14: =SUM(BI7:BI13) -> 0 | BJ14: =SUM(BJ7,BJ8,BJ9,BJ10,BJ11,BJ12,BJ13) -> 0 | BK14: =SUM(BK7,BK8,BK9,BK10,BK11,BK12,BK13) -> 0 | BL14: =SUM(BL7,BL8,BL9,BL10,BL11,BL12,BL13) -> 0 | BM14: =SUM(BM7,BM8,BM9,BM10,BM11,BM12,BM13) -> 0 | BN14: =SUM(BN7:BN13) -> 0 | BO14: =SUM(BO7:BO13) -> 173300

Sheet Summary
A1: Kingdom City Church Nanyuki
A2: Weekly & Monthly Collections vs Expenses Summary 2026
A4: Date | B4: Sunday | C4: Total Collections (KES) | D4: Total Expenses (KES) | E4: Net (Collections – Expenses) (KES) | F4: Notes
A5: January 2027
A6: 46026 | B6: Sunday 1 | C6: =Collections!E6 -> 0 | D6: =Expenses!C14 -> 0 | E6: =C6-D6 -> 0
A7: 46033 | B7: Sunday 2 | C7: =Collections!E7 -> 0 | D7: =Expenses!D14 -> 0 | E7: =C7-D7 -> 0
A8: 46040 | B8: Sunday 3 | C8: =Collections!E8 -> 0 | D8: =Expenses!E14 -> 0 | E8: =C8-D8 -> 0
A9: 46047 | B9: Sunday 4 | C9: =Collections!E9 -> 0 | D9: =Expenses!F14 -> 0 | E9: =C9-D9 -> 0
A10: Total – January 2027 | C10: =Collections!E10 -> 0 | D10: =Expenses!G14 -> 0 | E10: =C10-D10 -> 0
A11: February 2027
A12: 46054 | B12: Sunday 1 | C12: =Collections!E12 -> 0 | D12: =Expenses!H14 -> 0 | E12: =C12-D12 -> 0
A13: 46061 | B13: Sunday 2 | C13: =Collections!E13 -> 0 | D13: =Expenses!I14 -> 0 | E13: =C13-D13 -> 0
A14: 46068 | B14: Sunday 3 | C14: =Collections!E14 -> 0 | D14: =Expenses!J14 -> 0 | E14: =C14-D14 -> 0
A15: 46075 | B15: Sunday 4 | C15: =Collections!E15 -> 0 | D15: =Expenses!K14 -> 0 | E15: =C15-D15 -> 0
A16: Total – February 2027 | C16: =Collections!E16 -> 0 | D16: =Expenses!L14 -> 0 | E16: =C16-D16 -> 0
A17: March 2027
A18: 46082 | B18: Sunday 1 | C18: =Collections!E18 -> 0 | D18: =Expenses!M14 -> 0 | E18: =C18-D18 -> 0 | F18: Cash collections received up to 22.03.2026, was not banked but rather used for Weekly expenses on 22.03.2027
A19: 46089 | B19: Sunday 2 | C19: =Collections!E19 -> 3160 | D19: =Expenses!N14 -> 14700 | E19: =C19-D19 -> -11540
A20: 46096 | B20: Sunday 3 | C20: =Collections!E20 -> 6310 | D20: =Expenses!O14 -> 17200 | E20: =C20-D20 -> -10890
A21: 46103 | B21: Sunday 4 | C21: =Collections!E21 -> 4680 | D21: =Expenses!P14 -> 17200 | E21: =C21-D21 -> -12520
A22: 46110 | B22: Sunday 5 | C22: =Collections!E22 -> 4620 | D22: =Expenses!Q14 -> 17200 | E22: =C22-D22 -> -12580
A23: Total – March 2027 | C23: =Collections!E23 -> 18770 | D23: =Expenses!R14 -> 66300 | E23: =C23-D23 -> -47530
A24: April 2026
A25: 46117 | B25: Sunday 1 | C25: =Collections!E25 -> 12780 | D25: =Expenses!S14 -> 17200 | E25: =C25-D25 -> -4420
A26: 46124 | B26: Sunday 2 | C26: =Collections!E26 -> 6280 | D26: =Expenses!T14 -> 9700 | E26: =C26-D26 -> -3420
A27: 46131 | B27: Sunday 3 | C27: =Collections!E27 -> 7530.5 | D27: =Expenses!U14 -> 9700 | E27: =C27-D27 -> -2169.5
A28: 46138 | B28: Sunday 4 | C28: =Collections!E28 -> 6600 | D28: =Expenses!V14 -> 9700 | E28: =C28-D28 -> -3100
A29: Total – April | C29: =Collections!E29 -> 33190.5 | D29: =Expenses!W14 -> 46300 | E29: =C29-D29 -> -13109.5
A30: May 2026
A31: 46145 | B31: Sunday 1 | C31: =Collections!E31 -> 2740 | D31: =Expenses!X14 -> 9700 | E31: =C31-D31 -> -6960
A32: 46152 | B32: Sunday 2 | C32: =Collections!E32 -> 2770 | D32: =Expenses!Y14 -> 9700 | E32: =C32-D32 -> -6930
A33: 46159 | B33: Sunday 3 | C33: =Collections!E33 -> 11371 | D33: =Expenses!Z14 -> 9700 | E33: =C33-D33 -> 1671
A34: 46166 | B34: Sunday 4 | C34: =Collections!E34 -> 4110 | D34: =Expenses!AA14 -> 9700 | E34: =C34-D34 -> -5590
A35: 46173 | B35: Sunday 5 | C35: =Collections!E35 -> 1790 | D35: =Expenses!AB14 -> 12200 | E35: =C35-D35 -> -10410
A36: Total – May | C36: =Collections!E36 -> 22781 | D36: =Expenses!AC14 -> 51000 | E36: =C36-D36 -> -28219
A37: June 2026
A38: 46180 | B38: Sunday 1 | C38: =Collections!E38 -> 3545 | D38: =Expenses!AD14 -> 9700 | E38: =C38-D38 -> -6155
A39: 46187 | B39: Sunday 2 | C39: =Collections!E39 -> 0 | D39: =Expenses!AE14 -> 0 | E39: =C39-D39 -> 0
A40: 46194 | B40: Sunday 3 | C40: =Collections!E40 -> 0 | D40: =Expenses!AF14 -> 0 | E40: =C40-D40 -> 0
A41: 46201 | B41: Sunday 4 | C41: =Collections!E41 -> 0 | D41: =Expenses!AG14 -> 0 | E41: =C41-D41 -> 0
...

Sheet Cash flow
B1: Total cash collections | G1: 37830
A2: Add | B2: cash from bank - | D2: 46095 | F2: 20600
D3: 46116 | F3: 35550 | G3: =F2+F3 -> 56150
B4: total cash | G4: =G1+G3 -> 93980
B5: Less Total expenses | F5: 91000
B6: Balance | G6: =G4-F5 -> 2980
B7: Other expenses
B9: Purchase of Batteries | E9: 1820
B10: Tissue | E10: 360
B11: Repairs at the guest house
C12: Timber | D12: 1500
C13: Fundi | D13: 1300
C14: Nails | D14: 300
D15: Total | E15: =D12+D13+D14+E9+E10 -> 5280

Sheet Charts
A1: Kingdom City Church Nanyuki — Financial Charts 2026
A2: Live-linked from Collections, Expenses & Draft Budget sheets
A4: Month | B4: Collections | C4: Expenses | D4: Budget Income | E4: Budget Expenses | F4: Net
A5: Apr | B5: =Collections!E29 -> 33190.5 | C5: =Expenses!W14 -> 46300 | D5: ='Draft Budget'!D14 -> 0 | E5: ='Draft Budget'!D54 -> 135800 | F5: =B5-C5 -> -13109.5
A6: May | B6: =Collections!E36 -> 22781 | C6: =Expenses!AC14 -> 51000 | D6: ='Draft Budget'!E14 -> 0 | E6: ='Draft Budget'!E54 -> 0 | F6: =B6-C6 -> -28219
A7: Jun | B7: =Collections!E42 -> 3545 | C7: =Expenses!AH14 -> 9700 | D7: ='Draft Budget'!F14 -> 0 | E7: ='Draft Budget'!F54 -> 0 | F7: =B7-C7 -> -6155
A8: Jul | B8: =Collections!E48 -> 0 | C8: =Expenses!AM14 -> 0 | D8: ='Draft Budget'!G14 -> 0 | E8: ='Draft Budget'!G54 -> 0 | F8: =B8-C8 -> 0
A9: Aug | B9: =Collections!E55 -> 0 | C9: =Expenses!AS14 -> 0 | D9: ='Draft Budget'!H14 -> 0 | E9: ='Draft Budget'!H54 -> 0 | F9: =B9-C9 -> 0
A10: Sep | B10: =Collections!E61 -> 0 | C10: =Expenses!AX14 -> 0 | D10: ='Draft Budget'!I14 -> 0 | E10: ='Draft Budget'!I54 -> 0 | F10: =B10-C10 -> 0
A11: Oct | B11: =Collections!E67 -> 0 | C11: =Expenses!BC14 -> 0 | D11: ='Draft Budget'!J14 -> 0 | E11: ='Draft Budget'!J54 -> 0 | F11: =B11-C11 -> 0
A12: Nov | B12: =Collections!E74 -> 0 | C12: =Expenses!BI14 -> 0 | D12: ='Draft Budget'!K14 -> 0 | E12: ='Draft Budget'!K54 -> 0 | F12: =B12-C12 -> 0
A13: Dec | B13: =Collections!E80 -> 0 | C13: =Expenses!BN14 -> 0 | D13: ='Draft Budget'!L14 -> 0 | E13: ='Draft Budget'!L54 -> 0 | F13: =B13-C13 -> 0
A14: Jan | B14: =Collections!E10 -> 0 | C14: =Expenses!G14 -> 0 | D14: ='Draft Budget'!M14 -> 0 | E14: ='Draft Budget'!M54 -> 0 | F14: =B14-C14 -> 0
A15: Feb | B15: =Collections!E16 -> 0 | C15: =Expenses!L14 -> 0 | D15: ='Draft Budget'!N14 -> 0 | E15: ='Draft Budget'!N54 -> 0 | F15: =B15-C15 -> 0
A16: Mar | B16: =Collections!E23 -> 18770 | C16: =Expenses!R14 -> 66300 | D16: ='Draft Budget'!O14 -> 0 | E16: ='Draft Budget'!O54 -> 0 | F16: =B16-C16 -> -47530
A17: TOTAL | B17: =SUM(B5:B16) -> 78286.5 | C17: =SUM(C5:C16) -> 173300 | D17: =SUM(D5:D16) -> 0 | E17: =SUM(E5:E16) -> 135800 | F17: =SUM(F5:F16) -> -95013.5

Sheet Executive Summary
A1: Kingdom City Church Nanyuki
A2: EXECUTIVE FINANCIAL SUMMARY — 2026
A4: TOTAL COLLECTIONS YTD | C4: TOTAL EXPENSES YTD | E4: NET POSITION YTD | G4: TOTAL ARREARS
A5: =Collections!E81 -> 78286.5 | C5: =Expenses!BO14 -> 173300 | E5: =Collections!E81-Expenses!BO14 -> -95013.5 | G5: =SUM(Arrears!E5:E20) -> 233500
A9: MONTHLY PERFORMANCE SUMMARY
A10: Month | B10: Budgeted Income | C10: Actual Collections | D10: Actual Expenses | E10: Net (KES) | F10: Budget Surplus/(Deficit) | G10: Variance vs Budget | H10: Status
A11: Apr | B11: ='Draft Budget'!D14 -> 0 | C11: =Collections!E29 -> 33190.5 | D11: =Expenses!W14 -> 46300 | E11: =C11-D11 -> -13109.5 | F11: =B11-D11 -> -46300 | G11: =C11-B11 -> 33190.5 | H11: =IF(E11>=F11,"✓ On Track","▼ Behind") -> ✓ On Track
A12: May | B12: ='Draft Budget'!E14 -> 0 | C12: =Collections!E36 -> 22781 | D12: =Expenses!AC14 -> 51000 | E12: =C12-D12 -> -28219 | F12: =B12-D12 -> -51000 | G12: =C12-B12 -> 22781 | H12: =IF(E12>=F12,"✓ On Track","▼ Behind") -> ✓ On Track
A13: Jun | B13: ='Draft Budget'!F14 -> 0 | C13: =Collections!E42 -> 3545 | D13: =Expenses!AH14 -> 9700 | E13: =C13-D13 -> -6155 | F13: =B13-D13 -> -9700 | G13: =C13-B13 -> 3545 | H13: =IF(E13>=F13,"✓ On Track","▼ Behind") -> ✓ On Track
A14: Jul | B14: ='Draft Budget'!G14 -> 0 | C14: =Collections!E48 -> 0 | D14: =Expenses!AM14 -> 0 | E14: =C14-D14 -> 0 | F14: =B14-D14 -> 0 | G14: =C14-B14 -> 0 | H14: =IF(E14>=F14,"✓ On Track","▼ Behind") -> ✓ On Track
A15: Aug | B15: ='Draft Budget'!H14 -> 0 | C15: =Collections!E55 -> 0 | D15: =Expenses!AS14 -> 0 | E15: =C15-D15 -> 0 | F15: =B15-D15 -> 0 | G15: =C15-B15 -> 0 | H15: =IF(E15>=F15,"✓ On Track","▼ Behind") -> ✓ On Track
A16: Sep | B16: ='Draft Budget'!I14 -> 0 | C16: =Collections!E61 -> 0 | D16: =Expenses!AX14 -> 0 | E16: =C16-D16 -> 0 | F16: =B16-D16 -> 0 | G16: =C16-B16 -> 0 | H16: =IF(E16>=F16,"✓ On Track","▼ Behind") -> ✓ On Track
A17: Oct | B17: ='Draft Budget'!J14 -> 0 | C17: =Collections!E67 -> 0 | D17: =Expenses!BC14 -> 0 | E17: =C17-D17 -> 0 | F17: =B17-D17 -> 0 | G17: =C17-B17 -> 0 | H17: =IF(E17>=F17,"✓ On Track","▼ Behind") -> ✓ On Track
A18: Nov | B18: ='Draft Budget'!K14 -> 0 | C18: =Collections!E74 -> 0 | D18: =Expenses!BI14 -> 0 | E18: =C18-D18 -> 0 | F18: =B18-D18 -> 0 | G18: =C18-B18 -> 0 | H18: =IF(E18>=F18,"✓ On Track","▼ Behind") -> ✓ On Track
A19: Dec | B19: ='Draft Budget'!L14 -> 0 | C19: =Collections!E80 -> 0 | D19: =Expenses!BN14 -> 0 | E19: =C19-D19 -> 0 | F19: =B19-D19 -> 0 | G19: =C19-B19 -> 0 | H19: =IF(E19>=F19,"✓ On Track","▼ Behind") -> ✓ On Track
A20: Jan | B20: ='Draft Budget'!M14 -> 0 | C20: =Collections!E10 -> 0 | D20: =Expenses!G14 -> 0 | E20: =C20-D20 -> 0 | F20: =B20-D20 -> 0 | G20: =C20-B20 -> 0 | H20: =IF(E20>=F20,"✓ On Track","▼ Behind") -> ✓ On Track
A21: Feb | B21: ='Draft Budget'!N14 -> 0 | C21: =Collections!E16 -> 0 | D21: =Expenses!L14 -> 0 | E21: =C21-D21 -> 0 | F21: =B21-D21 -> 0 | G21: =C21-B21 -> 0 | H21: =IF(E21>=F21,"✓ On Track","▼ Behind") -> ✓ On Track
A22: Mar | B22: ='Draft Budget'!O14 -> 0 | C22: =Collections!E23 -> 18770 | D22: =Expenses!R14 -> 66300 | E22: =C22-D22 -> -47530 | F22: =B22-D22 -> -66300 | G22: =C22-B22 -> 18770 | H22: =IF(E22>=F22,"✓ On Track","▼ Behind") -> ✓ On Track
A23: YEAR TOTAL | B23: =SUM(B11:B22) -> 0 | C23: =SUM(C11:C22) -> 78286.5 | D23: =SUM(D11:D22) -> 173300 | E23: =SUM(E11:E22) -> -95013.5 | F23: =SUM(F11:F22) -> -173300 | G23: =SUM(G11:G22) -> 78286.5
A25: ARREARS SNAPSHOT
A26: Expense Item | B26: Period | C26: Amount Due (KES) | D26: Amount Paid (KES) | E26: Balance Owing (KES) | G26: Status | H26: Notes
A27: =Arrears!A5 -> Sanitary Bins & detergent | B27: =Arrears!B5 -> Jan – Mar 2026 | C27: =Arrears!C5 -> 3500 | D27: =Arrears!D5 -> 0 | E27: =Arrears!E5 -> 3500 | G27: =Arrears!G5 -> ⚠ UNPAID | H27: =Arrears!I5 -> NB – KES 3,500 unpaid
A28: =Arrears!A6 -> Rent | B28: =Arrears!B6 -> Nov – Dec 2025 | C28: =Arrears!C6 -> 95000 | D28: =Arrears!D6 -> 0 | E28: =Arrears!E6 -> 95000 | G28: =Arrears!G6 -> ⚠ UNPAID | H28: =Arrears!I6 -> Arrears outstanding
A29: =Arrears!A7 -> Beisa Hotel | B29: =Arrears!B7 -> 2025 | C29: =Arrears!C7 -> 20000 | D29: =Arrears!D7 -> 0 | E29: =Arrears!E7 -> 20000 | G29: =Arrears!G7 -> ⚠ UNPAID | H29: =Arrears!I7 -> Arrears outstanding
A30: =Arrears!A8 -> Iserve | B30: =Arrears!B8 -> 2025 | C30: =Arrears!C8 -> 60000 | D30: =Arrears!D8 -> 0 | E30: =Arrears!E8 -> 60000 | G30: =Arrears!G8 -> ⚠ UNPAID | H30: =Arrears!I8 -> Arrears outstanding
A31: =Arrears!A11 -> Nawasco | B31: =Arrears!B11 -> 0 | C31: =Arrears!C11 -> 0 | D31: =Arrears!D11 -> 0 | E31: =Arrears!E11 -> 0 | G31: =Arrears!G11 -> ✓ PAID | H31: =Arrears!I11 -> 0
A32: =Arrears!A12 -> Keyboardist | B32: =Arrears!B12 -> 0 | C32: =Arrears!C12 -> 0 | D32: =Arrears!D12 -> 0 | E32: =Arrears!E12 -> 0 | G32: =Arrears!G12 -> ✓ PAID | H32: =Arrears!I12 -> 0
A33: =Arrears!A13 -> Drummer | B33: =Arrears!B13 -> 0 | C33: =Arrears!C13 -> 0 | D33: =Arrears!D13 -> 0 | E33: =Arrears!E13 -> 0 | G33: =Arrears!G13 -> ✓ PAID | H33: =Arrears!I13 -> 0
A34: =Arrears!A14 -> Kids Teacher | B34: =Arrears!B14 -> 0 | C34: =Arrears!C14 -> 0 | D34: =Arrears!D14 -> 0 | E34: =Arrears!E14 -> 0 | G34: =Arrears!G14 -> ✓ PAID | H34: =Arrears!I14 -> 0
A35: =Arrears!A15 -> Caretaker | B35: =Arrears!B15 -> 0 | C35: =Arrears!C15 -> 0 | D35: =Arrears!D15 -> 0 | E35: =Arrears!E15 -> 0 | G35: =Arrears!G15 -> ✓ PAID | H35: =Arrears!I15 -> 0
A36: =Arrears!A16 -> Honorarium | B36: =Arrears!B16 -> 0 | C36: =Arrears!C16 -> 0 | D36: =Arrears!D16 -> 0 | E36: =Arrears!E16 -> 0 | G36: =Arrears!G16 -> ✓ PAID | H36: =Arrears!I16 -> 0
A37: =Arrears!A17 -> KPLC Tokens | B37: =Arrears!B17 -> 0 | C37: =Arrears!C17 -> 0 | D37: =Arrears!D17 -> 0 | E37: =Arrears!E17 -> 0 | G37: =Arrears!G17 -> ✓ PAID | H37: =Arrears!I17 -> 0
A38: =Arrears!A18 -> Extra Item 1 | B38: =Arrears!B18 -> 0 | C38: =Arrears!C18 -> 0 | D38: =Arrears!D18 -> 0 | E38: =Arrears!E18 -> 0 | G38: =Arrears!G18 -> ✓ PAID | H38: =Arrears!I18 -> 0
A39: =Arrears!A19 -> Extra Item 2 | B39: =Arrears!B19 -> 0 | C39: =Arrears!C19 -> 0 | D39: =Arrears!D19 -> 0 | E39: =Arrears!E19 -> 0 | G39: =Arrears!G19 -> ✓ PAID | H39: =Arrears!I19 -> 0
A40: =Arrears!A20 -> Extra Item 3 | B40: =Arrears!B20 -> 0 | C40: =Arrears!C20 -> 0 | D40: =Arrears!D20 -> 0 | E40: =Arrears!E20 -> 0 | G40: =Arrears!G20 -> ✓ PAID | H40: =Arrears!I20 -> 0
A41: TOTAL ARREARS OUTSTANDING | E41: =SUM(E27:E40) -> 178500
A65: Relevant | Relational | Refreshing
A66: Kingdom City Church Nanyuki | Finance Department | 2026

Sheet Exec Summary (Logo)
A1: Kingdom City Church Nanyuki
A3: EXECUTIVE FINANCIAL SUMMARY — 2026
A5: TOTAL COLLECTIONS YTD | C5: TOTAL EXPENSES YTD | E5: NET POSITION YTD | G5: TOTAL ARREARS
A6: =Collections!E81 -> 78286.5 | C6: =Expenses!BO14 -> 173300 | E6: =Collections!E81-Expenses!BO14 -> -95013.5 | G6: =SUM(Arrears!E5:E20) -> 233500
A10: MONTHLY PERFORMANCE SUMMARY
A11: Month | B11: Budgeted Income | C11: Actual Collections | D11: Actual Expenses | E11: Net (KES) | F11: Budget Surplus/(Deficit) | G11: Variance vs Budget | H11: Status
A12: Apr | B12: ='Draft Budget'!D14 -> 0 | C12: =Collections!E29 -> 33190.5 | D12: =Expenses!W14 -> 46300 | E12: =C12-D12 -> -13109.5 | F12: =B12-D12 -> -46300 | G12: =C12-B12 -> 33190.5 | H12: =IF(E12>=F12,"✓ On Track","▼ Behind") -> ✓ On Track
A13: May | B13: ='Draft Budget'!E14 -> 0 | C13: =Collections!E36 -> 22781 | D13: =Expenses!AC14 -> 51000 | E13: =C13-D13 -> -28219 | F13: =B13-D13 -> -51000 | G13: =C13-B13 -> 22781 | H13: =IF(E13>=F13,"✓ On Track","▼ Behind") -> ✓ On Track
A14: Jun | B14: ='Draft Budget'!F14 -> 0 | C14: =Collections!E42 -> 3545 | D14: =Expenses!AH14 -> 9700 | E14: =C14-D14 -> -6155 | F14: =B14-D14 -> -9700 | G14: =C14-B14 -> 3545 | H14: =IF(E14>=F14,"✓ On Track","▼ Behind") -> ✓ On Track
A15: Jul | B15: ='Draft Budget'!G14 -> 0 | C15: =Collections!E48 -> 0 | D15: =Expenses!AM14 -> 0 | E15: =C15-D15 -> 0 | F15: =B15-D15 -> 0 | G15: =C15-B15 -> 0 | H15: =IF(E15>=F15,"✓ On Track","▼ Behind") -> ✓ On Track
A16: Aug | B16: ='Draft Budget'!H14 -> 0 | C16: =Collections!E55 -> 0 | D16: =Expenses!AS14 -> 0 | E16: =C16-D16 -> 0 | F16: =B16-D16 -> 0 | G16: =C16-B16 -> 0 | H16: =IF(E16>=F16,"✓ On Track","▼ Behind") -> ✓ On Track
A17: Sep | B17: ='Draft Budget'!I14 -> 0 | C17: =Collections!E61 -> 0 | D17: =Expenses!AX14 -> 0 | E17: =C17-D17 -> 0 | F17: =B17-D17 -> 0 | G17: =C17-B17 -> 0 | H17: =IF(E17>=F17,"✓ On Track","▼ Behind") -> ✓ On Track
A18: Oct | B18: ='Draft Budget'!J14 -> 0 | C18: =Collections!E67 -> 0 | D18: =Expenses!BC14 -> 0 | E18: =C18-D18 -> 0 | F18: =B18-D18 -> 0 | G18: =C18-B18 -> 0 | H18: =IF(E18>=F18,"✓ On Track","▼ Behind") -> ✓ On Track
A19: Nov | B19: ='Draft Budget'!K14 -> 0 | C19: =Collections!E74 -> 0 | D19: =Expenses!BI14 -> 0 | E19: =C19-D19 -> 0 | F19: =B19-D19 -> 0 | G19: =C19-B19 -> 0 | H19: =IF(E19>=F19,"✓ On Track","▼ Behind") -> ✓ On Track
A20: Dec | B20: ='Draft Budget'!L14 -> 0 | C20: =Collections!E80 -> 0 | D20: =Expenses!BN14 -> 0 | E20: =C20-D20 -> 0 | F20: =B20-D20 -> 0 | G20: =C20-B20 -> 0 | H20: =IF(E20>=F20,"✓ On Track","▼ Behind") -> ✓ On Track
A21: Jan | B21: ='Draft Budget'!M14 -> 0 | C21: =Collections!E10 -> 0 | D21: =Expenses!G14 -> 0 | E21: =C21-D21 -> 0 | F21: =B21-D21 -> 0 | G21: =C21-B21 -> 0 | H21: =IF(E21>=F21,"✓ On Track","▼ Behind") -> ✓ On Track
A22: Feb | B22: ='Draft Budget'!N14 -> 0 | C22: =Collections!E16 -> 0 | D22: =Expenses!L14 -> 0 | E22: =C22-D22 -> 0 | F22: =B22-D22 -> 0 | G22: =C22-B22 -> 0 | H22: =IF(E22>=F22,"✓ On Track","▼ Behind") -> ✓ On Track
A23: Mar | B23: ='Draft Budget'!O14 -> 0 | C23: =Collections!E23 -> 18770 | D23: =Expenses!R14 -> 66300 | E23: =C23-D23 -> -47530 | F23: =B23-D23 -> -66300 | G23: =C23-B23 -> 18770 | H23: =IF(E23>=F23,"✓ On Track","▼ Behind") -> ✓ On Track
A24: YEAR TOTAL | B24: =SUM(B12:B23) -> 0 | C24: =SUM(C12:C23) -> 78286.5 | D24: =SUM(D12:D23) -> 173300 | E24: =SUM(E12:E23) -> -95013.5 | F24: =SUM(F12:F23) -> -173300 | G24: =SUM(G12:G23) -> 78286.5
A26: ARREARS SNAPSHOT
A27: Expense Item | B27: Period | C27: Amount Due (KES) | D27: Amount Paid (KES) | E27: Balance Owing (KES) | G27: Status | H27: Notes
A28: =Arrears!A5 -> Sanitary Bins & detergent | B28: =Arrears!B5 -> Jan – Mar 2026 | C28: =Arrears!C5 -> 3500 | D28: =Arrears!D5 -> 0 | E28: =Arrears!E5 -> 3500 | G28: =Arrears!G5 -> ⚠ UNPAID | H28: =Arrears!I5 -> NB – KES 3,500 unpaid
A29: =Arrears!A6 -> Rent | B29: =Arrears!B6 -> Nov – Dec 2025 | C29: =Arrears!C6 -> 95000 | D29: =Arrears!D6 -> 0 | E29: =Arrears!E6 -> 95000 | G29: =Arrears!G6 -> ⚠ UNPAID | H29: =Arrears!I6 -> Arrears outstanding
A30: =Arrears!A7 -> Beisa Hotel | B30: =Arrears!B7 -> 2025 | C30: =Arrears!C7 -> 20000 | D30: =Arrears!D7 -> 0 | E30: =Arrears!E7 -> 20000 | G30: =Arrears!G7 -> ⚠ UNPAID | H30: =Arrears!I7 -> Arrears outstanding
A31: =Arrears!A8 -> Iserve | B31: =Arrears!B8 -> 2025 | C31: =Arrears!C8 -> 60000 | D31: =Arrears!D8 -> 0 | E31: =Arrears!E8 -> 60000 | G31: =Arrears!G8 -> ⚠ UNPAID | H31: =Arrears!I8 -> Arrears outstanding
A32: =Arrears!A11 -> Nawasco | B32: =Arrears!B11 -> 0 | C32: =Arrears!C11 -> 0 | D32: =Arrears!D11 -> 0 | E32: =Arrears!E11 -> 0 | G32: =Arrears!G11 -> ✓ PAID | H32: =Arrears!I11 -> 0
A33: =Arrears!A12 -> Keyboardist | B33: =Arrears!B12 -> 0 | C33: =Arrears!C12 -> 0 | D33: =Arrears!D12 -> 0 | E33: =Arrears!E12 -> 0 | G33: =Arrears!G12 -> ✓ PAID | H33: =Arrears!I12 -> 0
A34: =Arrears!A13 -> Drummer | B34: =Arrears!B13 -> 0 | C34: =Arrears!C13 -> 0 | D34: =Arrears!D13 -> 0 | E34: =Arrears!E13 -> 0 | G34: =Arrears!G13 -> ✓ PAID | H34: =Arrears!I13 -> 0
A35: =Arrears!A14 -> Kids Teacher | B35: =Arrears!B14 -> 0 | C35: =Arrears!C14 -> 0 | D35: =Arrears!D14 -> 0 | E35: =Arrears!E14 -> 0 | G35: =Arrears!G14 -> ✓ PAID | H35: =Arrears!I14 -> 0
A36: =Arrears!A15 -> Caretaker | B36: =Arrears!B15 -> 0 | C36: =Arrears!C15 -> 0 | D36: =Arrears!D15 -> 0 | E36: =Arrears!E15 -> 0 | G36: =Arrears!G15 -> ✓ PAID | H36: =Arrears!I15 -> 0
A37: =Arrears!A16 -> Honorarium | B37: =Arrears!B16 -> 0 | C37: =Arrears!C16 -> 0 | D37: =Arrears!D16 -> 0 | E37: =Arrears!E16 -> 0 | G37: =Arrears!G16 -> ✓ PAID | H37: =Arrears!I16 -> 0
A38: =Arrears!A17 -> KPLC Tokens | B38: =Arrears!B17 -> 0 | C38: =Arrears!C17 -> 0 | D38: =Arrears!D17 -> 0 | E38: =Arrears!E17 -> 0 | G38: =Arrears!G17 -> ✓ PAID | H38: =Arrears!I17 -> 0
A39: =Arrears!A18 -> Extra Item 1 | B39: =Arrears!B18 -> 0 | C39: =Arrears!C18 -> 0 | D39: =Arrears!D18 -> 0 | E39: =Arrears!E18 -> 0 | G39: =Arrears!G18 -> ✓ PAID | H39: =Arrears!I18 -> 0
A40: =Arrears!A19 -> Extra Item 2 | B40: =Arrears!B19 -> 0 | C40: =Arrears!C19 -> 0 | D40: =Arrears!D19 -> 0 | E40: =Arrears!E19 -> 0 | G40: =Arrears!G19 -> ✓ PAID | H40: =Arrears!I19 -> 0
A41: =Arrears!A20 -> Extra Item 3 | B41: =Arrears!B20 -> 0 | C41: =Arrears!C20 -> 0 | D41: =Arrears!D20 -> 0 | E41: =Arrears!E20 -> 0 | G41: =Arrears!G20 -> ✓ PAID | H41: =Arrears!I20 -> 0
A42: TOTAL ARREARS OUTSTANDING | E42: =SUM(E28:E41) -> 178500
A66: Relevant | Relational | Refreshing
A67: Kingdom City Church Nanyuki | Finance Department | 2026

Sheet Arrears
A1: Kingdom City Church Nanyuki — Expense Arrears Tracker 2026
A2: Blue cells = input. Balance Owing auto-calculates. Status auto-updates: red = unpaid, green = paid.
A4: Expense Item | B4: Month Incurred | C4: Amount Due (KES) | D4: Amount Paid (KES) | E4: Balance Owing (KES) | F4: Date Paid | G4: Payment Status | H4: Paid By / Ref | I4: Notes
A5: Sanitary Bins & detergent | B5: Jan – Mar 2026 | C5: 3500 | D5: 0 | E5: =C5-D5 -> 3500 | G5: =IF(E5>0,"⚠ UNPAID",IF(E5=0,"✓ PAID","—")) -> ⚠ UNPAID | I5: NB – KES 3,500 unpaid
A6: Rent | B6: Nov – Dec 2025 | C6: 95000 | D6: 0 | E6: =C6-D6 -> 95000 | G6: =IF(E6>0,"⚠ UNPAID",IF(E6=0,"✓ PAID","—")) -> ⚠ UNPAID | I6: Arrears outstanding
A7: Beisa Hotel | B7: 2025 | C7: 20000 | D7: 0 | E7: =C7-D7 -> 20000 | G7: =IF(E7>0,"⚠ UNPAID",IF(E7=0,"✓ PAID","—")) -> ⚠ UNPAID | I7: Arrears outstanding
A8: Iserve | B8: 2025 | C8: 60000 | D8: 0 | E8: =C8-D8 -> 60000 | G8: =IF(E8>0,"⚠ UNPAID",IF(E8=0,"✓ PAID","—")) -> ⚠ UNPAID | I8: Arrears outstanding
A9: March Rent | B9: 46082 | C9: 55000 | E9: =C9-D9 -> 55000 | G9: =IF(E9>0,"⚠ UNPAID",IF(E9=0,"✓ PAID","—")) -> ⚠ UNPAID | I9: March 2026 Rent
E10: =C10-D10 -> 0
A11: Nawasco | C11: 0 | D11: 0 | E11: =C11-D11 -> 0 | G11: =IF(E11>0,"⚠ UNPAID",IF(E11=0,"✓ PAID","—")) -> ✓ PAID
A12: Keyboardist | C12: 0 | D12: 0 | E12: =C12-D12 -> 0 | G12: =IF(E12>0,"⚠ UNPAID",IF(E12=0,"✓ PAID","—")) -> ✓ PAID
A13: Drummer | C13: 0 | D13: 0 | E13: =C13-D13 -> 0 | G13: =IF(E13>0,"⚠ UNPAID",IF(E13=0,"✓ PAID","—")) -> ✓ PAID
A14: Kids Teacher | C14: 0 | D14: 0 | E14: =C14-D14 -> 0 | G14: =IF(E14>0,"⚠ UNPAID",IF(E14=0,"✓ PAID","—")) -> ✓ PAID
A15: Caretaker | C15: 0 | D15: 0 | E15: =C15-D15 -> 0 | G15: =IF(E15>0,"⚠ UNPAID",IF(E15=0,"✓ PAID","—")) -> ✓ PAID
A16: Honorarium | C16: 0 | D16: 0 | E16: =C16-D16 -> 0 | G16: =IF(E16>0,"⚠ UNPAID",IF(E16=0,"✓ PAID","—")) -> ✓ PAID
A17: KPLC Tokens | C17: 0 | D17: 0 | E17: =C17-D17 -> 0 | G17: =IF(E17>0,"⚠ UNPAID",IF(E17=0,"✓ PAID","—")) -> ✓ PAID
A18: Extra Item 1 | C18: 0 | D18: 0 | E18: =C18-D18 -> 0 | G18: =IF(E18>0,"⚠ UNPAID",IF(E18=0,"✓ PAID","—")) -> ✓ PAID
A19: Extra Item 2 | C19: 0 | D19: 0 | E19: =C19-D19 -> 0 | G19: =IF(E19>0,"⚠ UNPAID",IF(E19=0,"✓ PAID","—")) -> ✓ PAID
A20: Extra Item 3 | C20: 0 | D20: 0 | E20: =C20-D20 -> 0 | G20: =IF(E20>0,"⚠ UNPAID",IF(E20=0,"✓ PAID","—")) -> ✓ PAID
A21: TOTAL ARREARS OUTSTANDING | C21: =SUM(C5:C20) -> 233500 | D21: =SUM(D5:D20) -> 0 | E21: =SUM(E5:E20) -> 233500

Sheet Breakdown
A1: STATIC RECORD — Kingdom City Church Nanyuki | March 2026 Breakdown (values only, not linked)
P2: Denomination | Q2: Units | R2: Total
B3: MARCH 2026 | P3: 1000 | Q3: 1 | R3: =Q3*P3 -> 1000
B4: 46082 | C4: Sunday 1 | D4: 4290 | E4: 0 | F4: 4290 | G4: 4000 | P4: 500 | Q4: 0 | R4: =Q4*P4 -> 0
B5: 46089 | C5: Sunday 2 | D5: 3160 | E5: 0 | F5: 3160 | G5: 2500 | P5: 200 | Q5: 1 | R5: =Q5*P5 -> 200
B6: 46096 | C6: Sunday 3 | D6: 6310 | E6: 0 | F6: 6310 | L6: Standard Sunday expenses | P6: 100 | Q6: 4 | R6: =Q6*P6 -> 400
B7: 46103 | C7: Sunday 4 | D7: 4680 | E7: 0 | F7: 4680 | G7: 5000 | L7: Keys | M7: 2500 | P7: 50 | Q7: 3 | R7: =Q7*P7 -> 150
B8: 46110 | D8: 0 | E8: 0 | F8: 0 | L8: Drumer | M8: 2500 | P8: 40 | Q8: 0 | R8: =Q8*P8 -> 0
B9: Total – MARCH | D9: 18440 | E9: 0 | F9: 18440 | L9: Kkids | M9: 2500 | P9: 20 | Q9: 2 | R9: =Q9*P9 -> 40
B10: Cash handed over by Rev. Peter | F10: 12200 | R10: =Q10*P10 -> 0
A11: 14.03.2026 | B11: Cash withdrawal | F11: 20600 | L11: Caretaker | M11: 4200 | P11: 10 | Q11: 0 | R11: =Q11*P11 -> 0
B12: Total cash in hand | F12: 51240 | L12: KPLC Tokens | M12: 500 | P12: 5 | R12: =Q12*P12 -> 0
M13: 12200 | P13: 1 | R13: =Q13*P13 -> 0
A14: 08.03.2026 | B14: Standard Sunday expenses | E14: 12200 | G14: 1,000 Mpesa fare -kim | Q14: Total | R14: =SUM(R3:R13) -> 1790
B15: Honorarium (Rev. Andrew) | E15: 4000
B16: KPLC | E16: 500 | G16: Mpesa -kim
B17: Tissue | E17: 360
A19: 15.03.2026 | B19: Standard Sunday expenses | E19: 12200 | G19: 1,000 Mpesa fare -kim
B20: Honorarium (Rev. Andrew) | E20: 5000 | G20: Cash 4,000 - Mpesa 1,000-kim
B21: KPLC | E21: 500 | G21: Mpesa -kim
B22: Sanitary bins | E22: 1000 | G22: NB- 3,000 unpaid
E23: 0
A24: 22.03.2026 | B24: Standard Sunday expenses | E24: 12200 | G24: 1,000 Mpesa fare -kim
B25: Honorarium (Rev. Andrew) | E25: 5000
B26: KPLC | E26: 500 | G26: Mpesa -kim
A27: 23.03.2026 | B27: Purchase of industrial gloves | E27: 600
E28: 0
E29: 0
E30: 0
E31: 0
E32: 0
B33: ARREARS
A34: 1 | B34: Rent | E34: 95000 | G34: Arrears
A35: 2 | B35: Beisa Hotel | E35: 20000 | G35: Arrears
A36: 3 | B36: Iserve | E36: 60000 | G36: Arrears
A37: 4 | B37: Sanitary bins | E37: 3000
A38: 5 | B38: Nawasco | E38: 500
J40: 19.05.2026 | K40: 3500

Sheet Sheet1
B1: monthy
B2: finaces
B3: membership
B4: reaching out to friends
B5: maintaining the current members and tryong to concentrate on the people in church - ambience, programmes , different ways of engaging online prayers
B6: Website,
B7: what do we need
B8: kkis
B9: finance
B10: leaders
B11: admin team
B12: worship team

Sheet Draft Budget
A1: KINGDOM CITY CHURCH NANYUKI — BUDGET
G2: FINANCIAL YEAR 2026/2027
A4: NO. | B4: PARTICULARS | C4: Codes | D4: APRIL | E4: MAY | F4: JUNE | G4: JULY | H4: AUGUST | I4: SEPTEMBER | J4: OCTOBER | K4: NOVEMBER | L4: DECEMBER | M4: JANUARY | N4: FEBRUARY | O4: MARCH | P4: TOTALS
B5: INCOMES
A6: 1 | B6: Offerings | C6: 001/1/005 | P6: =SUM(D6:O6) -> 0
A7: 2 | B7: Tithe | C7: 001/1/010 | P7: =SUM(D7:O7) -> 0
B8: Donation/Grants-Cash | C8: 001/1/015 | P8: =SUM(D8:O8) -> 0
B9: Donation/Grants-Kind | C9: 001/1/020 | P9: =SUM(D9:O9) -> 0
B10: Soko Sales | C10: 001/1/025 | P10: =SUM(D10:O10) -> 0
B11: Gain on Disposals | C11: 001/1/030 | P11: =SUM(D11:O11) -> 0
A12: 3 | B12: Other Incomes | C12: 001/1/035 | P12: =SUM(D12:O12) -> 0
B14: Totals | D14: =SUM(D6:D12) -> 0 | E14: =SUM(E6:E12) -> 0 | F14: =SUM(F6:F12) -> 0 | G14: =SUM(G6:G12) -> 0 | H14: =SUM(H6:H12) -> 0 | I14: =SUM(I6:I12) -> 0 | J14: =SUM(J6:J12) -> 0 | K14: =SUM(K6:K12) -> 0 | ... O14: =SUM(O6:O12) -> 0 | P14: =SUM(D14:O14) -> 0
B16: EXPENSES
B17: Administration
A18: 1 | B18: Rent | C18: 001/2/001 | D18: 55000 | P18: =SUM(D18:O18) -> 55000
A19: 2 | B19: Water | C19: 001/2/002 | D19: 2000 | P19: =SUM(D19:O19) -> 2000
A20: 3 | B20: Electricity | C20: 001/2/003 | D20: 2000 | P20: =SUM(D20:O20) -> 2000
B21: Transport | C21: 001/2/004 | D21: 0
A22: 4 | B22: Insurance | C22: 001/2/005 | P22: =SUM(D22:O22) -> 0
B23: Security | C23: 001/2/006 | P23: =SUM(D23:O23) -> 0
B24: Communication/Telephone | C24: 001/2/007 | D24: 2000 | P24: =SUM(D24:O24) -> 2000
B25: Stationery | C25: 001/2/008 | D25: 2000 | P25: =SUM(D25:O25) -> 2000
B26: Refreshments | C26: 001/2/009 | P26: =SUM(D26:O26) -> 0
B27: Health & Safety(Fumigation/F.Extiguishers) | C27: 001/2/010 | D27: 1000
B28: Hospitality | C28: 001/2/011 | P28: =SUM(D28:O28) -> 0
B29: Detergents & Toiletries | C29: 001/2/012 | D29: 2000 | P29: =SUM(D29:O29) -> 2000
B30: Consultancy Fee | C30: 001/2/013 | P30: =SUM(D30:O30) -> 0
B31: Repair & Maintenance | C31: 001/2/014 | D31: 1000 | P31: =SUM(D31:O31) -> 1000
B32: Licences | C32: 001/2/015 | D32: 0 | P32: =SUM(D32:O32) -> 0
B33: Audit Fees | C33: 001/2/016 | P33: =SUM(D33:O33) -> 0
B34: Totals | D34: =SUM(D18:D33) -> 67000 | E34: =SUM(E18:E33) -> 0 | F34: =SUM(F18:F33) -> 0 | G34: =SUM(G18:G33) -> 0 | H34: =SUM(H18:H33) -> 0 | I34: =SUM(I18:I33) -> 0 | J34: =SUM(J18:J33) -> 0 | K34: =SUM(K18:K33) -> 0 | ... P34: =SUM(P18:P33) -> 66000
B35: Ministry & Departments
B36: K.Kids | C36: 001/3/001 | D36: 10000 | E36: (Assuming Kes 2,500 is paid per Sunday) | P36: =SUM(D36:O36) -> 10000
B37: Worship & Services | C37: 001/3/002 | D37: 20000 | E37: (assuming Kes 5,000 is paid per Sunday to the drummer & Keyboardist @ 2,500) | P37: =SUM(D37:O37) -> 20000
B38: Discipleship Programes | C38: 001/3/003 | P38: =SUM(D38:O38) -> 0
B39: Production, Sound & Lighting | C39: 001/3/004 | P39: =SUM(D39:O39) -> 0
B40: Wages | C40: 001/3/005 | D40: 16800 | E40: ( For the caretaker with a weekly pay of Kes. 4,200)
B41: Training & Development | C41: 001/3/006 | P41: =SUM(D41:O41) -> 0
B42: Pastoral Allowances/ Salaries | C42: 001/3/007
B43: Pastoral Care | C43: 001/3/008
...
